#VRML_SIM R2021a utf8
WorldInfo {
  coordinateSystem "NUE"
}
Viewpoint {
  orientation -0.17060994352542383 -0.9497410201495932 -0.262458076300695 2.05843873018216
  position -2.8604249820506014 2.132303530867589 -1.097171968181518
}
TexturedBackground {
}
TexturedBackgroundLight {
}
RectangleArena {
  floorSize 1 3
  wallThickness 1e-09
  wallHeight 1e-05
}
RoCKInShelf {
  translation 0.27 0.01 0
}
RoCKInShelf {
  translation 0.27 0.01 0.63
  name "RoCKIn shelf(1)"
}
RoCKInShelf {
  translation 0.27 0.01 -0.65
  name "RoCKIn shelf(2)"
}
RoCKInShelf {
  translation 0.27 0.53 0
  name "RoCKIn shelf(3)"
}
RoCKInShelf {
  translation 0.27 0.53 0.63
  name "RoCKIn shelf(4)"
}
RoCKInShelf {
  translation 0.27 0.52 -0.65
  name "RoCKIn shelf(5)"
}
Robot {
  translation 0.040322 0.0306035 -0.000307
  children [
    DEF HORIZ_GANTRY Group {
      children [
        DEF HORIZ_MOVER Transform {
          translation 0 -0.04 0.01
          children [
            DEF VERTCAL_GANTRY_ROD_4 Solid {
              translation -0.2 0.5 -0.98
              children [
                DEF GANTRY_ROD Shape {
                  appearance DEF VERTICAL_GANTRY_APPEARANCE Appearance {
                    material Material {
                      diffuseColor 0.3 0.3 0.9
                      emissiveColor 0 0 1
                    }
                  }
                  geometry DEF VERTICAL_GANTRY Box {
                    size 0.05 1.2 0.05
                  }
                }
              ]
              name "VERTICAL_GANTRY_ROD_1(3)"
              boundingObject USE VERTICAL_GANTRY
              physics Physics {
              }
            }
            DEF VERTCAL_GANTRY_ROD_3 Solid {
              translation 0.03 0.5 -0.98
              children [
                DEF GANTRY_ROD Shape {
                  appearance DEF VERTICAL_GANTRY_APPEARANCE Appearance {
                    material Material {
                      diffuseColor 0.3 0.3 0.9
                      emissiveColor 0 0 1
                    }
                  }
                  geometry DEF VERTICAL_GANTRY Box {
                    size 0.05 1.2 0.05
                  }
                }
              ]
              name "VERTICAL_GANTRY_ROD_1(2)"
              boundingObject USE VERTICAL_GANTRY
              physics Physics {
              }
            }
            DEF VERTCAL_GANTRY_ROD_2 Solid {
              translation -0.2 0.5 0.96
              children [
                DEF GANTRY_ROD Shape {
                  appearance DEF VERTICAL_GANTRY_APPEARANCE Appearance {
                    material Material {
                      diffuseColor 0.3 0.3 0.9
                      emissiveColor 0 0 1
                    }
                  }
                  geometry DEF VERTICAL_GANTRY Box {
                    size 0.05 1.2 0.05
                  }
                }
              ]
              name "VERTICAL_GANTRY_ROD_1(1)"
              boundingObject USE VERTICAL_GANTRY
              physics Physics {
              }
            }
            DEF HORIZMOVER Shape {
              appearance Appearance {
                material Material {
                  diffuseColor 0.3 0.3 0.8
                  emissiveColor 0.3 0.3 0.8
                }
              }
              geometry Box {
                size 0.2 0.04 0.5
              }
            }
            DEF VERTCAL_GANTRY_ROD Solid {
              translation 0.03 0.5 0.96
              children [
                DEF GANTRY_ROD Shape {
                  appearance DEF VERTICAL_GANTRY_APPEARANCE Appearance {
                    material Material {
                      diffuseColor 0.3 0.3 0.9
                      emissiveColor 0 0 1
                    }
                  }
                  geometry DEF VERTICAL_GANTRY Box {
                    size 0.05 1.2 0.05
                  }
                }
              ]
              name "VERTICAL_GANTRY_ROD_1"
              boundingObject USE VERTICAL_GANTRY
              physics Physics {
              }
            }
          ]
        }
        DEF VERT_GANTRY_REST Solid {
          translation -0.09 -0.01 -0.01
          children [
            SliderJoint {
              jointParameters JointParameters {
                axis 0 1 0
                maxStop 1
                staticFriction 10
              }
              device [
                Brake {
                  name "vertical brake"
                }
                LinearMotor {
                  name "vertical linear motor"
                  maxPosition 0.9
                  maxForce 7
                }
              ]
              endPoint Solid {
                translation 0 0.15 0
                children [
                  Group {
                    children [
                      SliderJoint {
                        jointParameters JointParameters {
                        }
                        device [
                          Brake {
                            name "horizontal brake"
                          }
                          LinearMotor {
                            name "horizontal linear motor"
                            minPosition -0.98
                            maxPosition 0.75
                          }
                        ]
                        endPoint DEF HORIZ_MOVER Solid {
                          children [
                            Shape {
                              appearance Appearance {
                                material Material {
                                  ambientIntensity 0.5
                                  diffuseColor 0.8 0.3 0.8
                                  emissiveColor 0.4 0 0.4
                                }
                              }
                              geometry Box {
                                size 0.2 0.04 0.5
                              }
                            }
                          ]
                          name "HORIZ_MOVER"
                        }
                      }
                      DEF HORIZ_GANTRY_ROD_2 Solid {
                        translation 0.11 0 0.01
                        children [
                          Shape {
                            appearance Appearance {
                              material Material {
                                diffuseColor 0.5 0.2 0.5
                                emissiveColor 0.7 0 0.7
                              }
                            }
                            geometry Box {
                              size 0.02 0.02 2
                            }
                          }
                        ]
                        name "solid(1)"
                      }
                      DEF HORIZ_GANTRY_ROD Solid {
                        translation -0.11 0 0.01
                        children [
                          Shape {
                            appearance Appearance {
                              material Material {
                                diffuseColor 0.5 0.2 0.5
                                emissiveColor 0.7 0 0.7
                              }
                            }
                            geometry Box {
                              size 0.02 0.02 2
                            }
                          }
                        ]
                      }
                    ]
                  }
                ]
              }
            }
            Shape {
              geometry Box {
                size 0.3 0.01 1.9
              }
            }
          ]
        }
      ]
    }
  ]
  controller "HORIZONTAL_CONTROLLER"
}
